#VRML_SIM R2023a utf8

EXTERNPROTO "https://raw.githubusercontent.com/cyberbotics/webots/R2023a/projects/objects/backgrounds/protos/TexturedBackground.proto"
EXTERNPROTO "https://raw.githubusercontent.com/cyberbotics/webots/R2023a/projects/objects/backgrounds/protos/TexturedBackgroundLight.proto"
EXTERNPROTO "https://raw.githubusercontent.com/cyberbotics/webots/R2023a/projects/objects/floors/protos/Floor.proto"
EXTERNPROTO "../protos/baxter_xacro.proto"

WorldInfo {
  basicTimeStep 16
}
Viewpoint {
  orientation -0.2986563526879307 0.07418425047232033 0.9514731104876281 2.677439996130917
  position 5.333534002776573 -5.315395335542727 5.211162138501
}
TexturedBackground {
}
TexturedBackgroundLight {
}
Floor {
  tileSize 0.2 0.2
}
Solid {
  translation 0 0.5 0.025
  children [
    DEF WALL_SHAPE Shape {
      appearance PBRAppearance {
        baseColor 0 0 1
        roughness 0.5
        metalness 0
      }
      geometry Box {
        size 1 0.01 0.05
      }
    }
  ]
  name "solid(2)"
  boundingObject USE WALL_SHAPE
}
Solid {
  translation 0 -0.5 0.025
  children [
    USE WALL_SHAPE
  ]
  name "solid(3)"
  boundingObject USE WALL_SHAPE
}
Solid {
  translation 0.5 0 0.025
  rotation 0 0 1 1.5707996938995747
  children [
    USE WALL_SHAPE
  ]
  name "solid(4)"
  boundingObject USE WALL_SHAPE
}
Solid {
  translation -0.5 0 0.025
  rotation 0 0 1 1.5707996938995747
  children [
    USE WALL_SHAPE
  ]
  name "solid(5)"
  boundingObject USE WALL_SHAPE
}
Robot {
  translation 0 0 0.04
  children [
    DistanceSensor {
      translation 0.1 -0.025 0
      rotation 0 0 1 -0.3
      children [
        DEF DS Shape {
          appearance PBRAppearance {
            baseColor 0 0 1
            roughness 1
            metalness 0
          }
          geometry Box {
            size 0.01 0.01 0.01
          }
        }
      ]
      name "ds_right"
      boundingObject USE DS
    }
    DistanceSensor {
      translation 0.1 0.025 0
      rotation 0 0 1 0.3
      children [
        USE DS
      ]
      name "ds_left"
      boundingObject USE DS
    }
    DEF BOX_SHAPE Shape {
      appearance PBRAppearance {
        baseColor 1 0 0
        roughness 0.5
        metalness 0
      }
      geometry Box {
        size 0.2 0.1 0.05
      }
    }
    HingeJoint {
      jointParameters HingeJointParameters {
        axis 0 1 0
        anchor 0.05 0.06 0
      }
      device [
        RotationalMotor {
          name "wheel1"
        }
      ]
      endPoint Solid {
        translation 0.05 0.06 0
        rotation 1 0 0 1.5708
        children [
          DEF WHEEL Shape {
            appearance PBRAppearance {
              baseColor 0 1 0
              roughness 1
              metalness 0
            }
            geometry Cylinder {
              height 0.02
              radius 0.04
            }
          }
        ]
        name "WHEEL1"
        boundingObject USE WHEEL
        physics DEF WHEEL_PH Physics {
        }
      }
    }
    HingeJoint {
      jointParameters HingeJointParameters {
        axis 0 1 0
        anchor 0.05 -0.06 0
      }
      device [
        RotationalMotor {
          name "wheel2"
        }
      ]
      endPoint Solid {
        translation 0.05 -0.06 0
        rotation -1 0 0 1.5708
        children [
          USE WHEEL
        ]
        name "WHEEL2"
        boundingObject USE WHEEL
        physics USE WHEEL_PH
      }
    }
    HingeJoint {
      jointParameters HingeJointParameters {
        axis 0 1 0
        anchor -0.05 0.06 0
      }
      device [
        RotationalMotor {
          name "wheel3"
        }
      ]
      endPoint Solid {
        translation -0.05 0.06 0
        rotation 1 0 0 1.5708
        children [
          USE WHEEL
        ]
        name "WHEEL3"
        boundingObject USE WHEEL
        physics USE WHEEL_PH
      }
    }
    HingeJoint {
      jointParameters HingeJointParameters {
        axis 0 1 0
        anchor -0.05 -0.06 0
      }
      device [
        RotationalMotor {
          name "wheel4"
        }
      ]
      endPoint Solid {
        translation -0.05 -0.06 0
        rotation -1 0 0 1.5708
        children [
          USE WHEEL
        ]
        name "WHEEL4"
        boundingObject USE WHEEL
        physics USE WHEEL_PH
      }
    }
  ]
  boundingObject USE BOX_SHAPE
  physics Physics {
  }
  controller "4_Wheel_Robot"
}
baxter_xacro {
  translation 0.06 -3.55 1.66
  controller "baxter_arm_motor"
  selfCollision TRUE
}
