#VRML_SIM R2023a utf8
PROTO FourWheelsRobot [
  field SFVec3f    translation  0 0 0
  field SFRotation rotation     0 0 1 0
  field SFFloat    bodyMass     1
  field SFString robotName "Untitled"
]
{
  Robot {
  name IS robotName
  translation IS translation
  rotation IS rotation
  name "robot1"
  children [
    DistanceSensor {
      translation 0.1 -0.025 0
      rotation 0 0 1 -0.3
      children [
        DEF DS Shape {
          appearance PBRAppearance {
            baseColor 0 0 1
            roughness 1
            metalness 0
          }
          geometry Box {
            size 0.01 0.01 0.01
          }
        }
      ]
      name "ds_right"
      boundingObject USE DS
    }
    DistanceSensor {
      translation 0.1 0.025 0
      rotation 0 0 1 0.3
      children [
        USE DS
      ]
      name "ds_left"
      boundingObject USE DS
    }
    DEF BOX_SHAPE Shape {
      appearance PBRAppearance {
        baseColor 1 0 0
        roughness 0.5
        metalness 0
      }
      geometry Box {
        size 0.2 0.1 0.05
      }
    }
    HingeJoint {
      jointParameters HingeJointParameters {
        axis 0 1 0
        anchor 0.05 0.06 0
      }
      device [
        RotationalMotor {
          name "wheel1"
        }
      ]
      endPoint Solid {
        translation 0.05 0.06 0
        rotation 1 0 0 1.5708
        children [
          DEF WHEEL Shape {
            appearance PBRAppearance {
              baseColor 0 1 0
              roughness 1
              metalness 0
            }
            geometry Cylinder {
              height 0.02
              radius 0.04
            }
          }
        ]
        name "WHEEL1"
        boundingObject USE WHEEL
        physics DEF WHEEL_PH Physics {
        }
      }
    }
    HingeJoint {
      jointParameters HingeJointParameters {
        axis 0 1 0
        anchor 0.05 -0.06 0
      }
      device [
        RotationalMotor {
          name "wheel2"
        }
      ]
      endPoint Solid {
        translation 0.05 -0.06 0
        rotation -1 0 0 1.5708
        children [
          USE WHEEL
        ]
        name "WHEEL2"
        boundingObject USE WHEEL
        physics USE WHEEL_PH
      }
    }
    HingeJoint {
      jointParameters HingeJointParameters {
        axis 0 1 0
        anchor -0.05 0.06 0
      }
      device [
        RotationalMotor {
          name "wheel3"
        }
      ]
      endPoint Solid {
        translation -0.05 0.06 0
        rotation 1 0 0 1.5708
        children [
          USE WHEEL
        ]
        name "WHEEL3"
        boundingObject USE WHEEL
        physics USE WHEEL_PH
      }
    }
    HingeJoint {
      jointParameters HingeJointParameters {
        axis 0 1 0
        anchor -0.05 -0.06 0
      }
      device [
        RotationalMotor {
          name "wheel4"
        }
      ]
      endPoint Solid {
        translation -0.05 -0.06 0
        rotation -1 0 0 1.5708
        children [
          USE WHEEL
        ]
        name "WHEEL4"
        boundingObject USE WHEEL
        physics USE WHEEL_PH
      }
    }
  ]
  boundingObject USE BOX_SHAPE
  physics Physics {
    mass IS bodyMass
  }
  controller "4_Wheel_Robot"
}
}